<?xml version="1.0"?>

<robot name="boties">
	<material name="white">
		<color rgba="1 1 1 1"/>
	</material>
	<material name="brown">
		<color rgba="0.58 0.39 0.27 1"/>
	</material>
	<link name="base_link">
		<visual>
			<geometry>
				<cylinder length="0.08" radius="0.1"/>
			</geometry>
			<material name="brown"/>
		</visual>
		<collision>
			<geometry>
				<cylinder length="0.01" radius="0.1"/>
			</geometry>
		</collision>
		<inertial>
			<mass value="20"/>
			<inertia ixx="0.0168" iyy="0.0168" izz="0.01" ixy="0.0" ixz="0.0" iyz="0.0"/>
		</inertial>
	</link>
	<link name="dummy_link"></link>
	<link name="leftWheel_link">
		<visual>
			<geometry>
				<cylinder length="0.05" radius="0.05"/>
			</geometry>
			<material name="white"/>
		</visual>
		<collision>
			<geometry>
				<cylinder length="0.05" radius="0.05"/>
			</geometry>
		</collision>
		<inertial>
			<mass value="10"/>
			<inertia ixx="0.00625" iyy="0.00625" izz="0.0125" ixy="0.0" ixz="0.0" iyz="0.0"/>
		</inertial>
	</link>
	<link name="rightWheel_link">
		<visual>
			<geometry>
				<cylinder length="0.05" radius="0.05"/>
			</geometry>
			<material name="white"/>
		</visual>
		<collision>
			<geometry>
				<cylinder length="0.05" radius="0.05"/>
			</geometry>
		</collision>
		<inertial>
			<mass value="10"/>
			<inertia ixx="0.00625" iyy="0.00625" izz="0.0125" ixy="0.0" ixz="0.0" iyz="0.0"/>
		</inertial>
	</link>
	<link name="sphere_link">
		<visual>
			<geometry>
				<sphere radius="0.05"/>
			</geometry>
			<material name="white"/>
		</visual>
		<collision>
			<geometry>
				<sphere radius="0.05"/>
			</geometry>
		</collision>
		<inertial>
			<mass value="20"/>
			<inertia ixx="0.0168" iyy="0.0168" izz="0.01" ixy="0.0" ixz="0.0" iyz="0.0"/>
		</inertial>
	</link>
	<joint name="dummy_joint" type="continuous">
		<parent link="base_link" />
		<child  link="dummy_link" />
	</joint>
	<joint name="baseToLeftWheel_joint" type="continuous">
		<axis   xyz="0 0 1"/>
		<parent link="base_link" />
		<child  link="leftWheel_link" />
		<origin rpy="0 1.57075 0" xyz="0.1 0.05 0" />
	</joint>
	<joint name="baseToRightWheel_joint" type="continuous">
		<axis   xyz="0 0 1"/>
		<parent link="base_link" />
		<child  link="rightWheel_link" />
		<origin rpy="0 1.57075 0" xyz="-0.1 0.05 0" />
	</joint>
	<joint name="baseToSphere_joint" type="continuous">
		<axis   xyz="1 1 1"/>
		<parent link="base_link" />
		<child  link="sphere_link" />
		<origin rpy="0 0 0" xyz="0 -0.1 0" />
	</joint>
	<transmission name="leftWheel_trans">
		<type>transmission_interface/SimpleTransmission</type>
		<actuator name="leftWheel_motor">
			<mechanicalReduction>1</mechanicalReduction>
		</actuator>
		<joint name="baseToLeftWheel_joint">
			<hardwareInterface>VelocityJointInterface</hardwareInterface>
		</joint>
	</transmission>
	<transmission name="rightWheel_trans">
		<type>transmission_interface/SimpleTransmission</type>
		<actuator name="rightWheel_motor">
			<mechanicalReduction>1</mechanicalReduction>
		</actuator>
		<joint name="baseToRightWheel_joint">
			<hardwareInterface>VelocityJointInterface</hardwareInterface>
		</joint>
	</transmission>
	<gazebo reference="leftWheel_link">
		<mu1 value="200.0"/>
		<mu2 value="100.0"/>
		<kp value="10000000.0"/>
		<kd value="1.0"/>
		<material>Gazebo/Grey</material>
	</gazebo>
	<gazebo reference="rightWheel_link">
		<mu1 value="200.0"/>
		<mu2 value="100.0"/>
		<kp value="10000000.0"/>
		<kd value="1.0"/>
		<material>Gazebo/Grey</material>
	</gazebo>
	<gazebo>
		<plugin name="gazebo_ros_control" filename="libgazebo_ros_control.so">
			<robotNamespace></robotNamespace>
		</plugin>
	</gazebo>
</robot>

